Traceback (most recent call last):
  File "src/3d/continue_int.py", line 271, in <module>
    continue_integration(filename)
  File "src/3d/continue_int.py", line 27, in continue_integration
    rng_draws = data['draws']
  File "/uufs/chpc.utah.edu/common/home/u0946770/software/pkg/miniconda3/envs/rolling/lib/python3.8/site-packages/numpy/lib/npyio.py", line 259, in __getitem__
    raise KeyError("%s is not a file in the archive" % key)
KeyError: 'draws is not a file in the archive'
